Load settings
Attempting to readC:\Users\Giogina\AppData\Roaming\SpectraMatcher\config\settings.json...
New called 
init called 
Fonts path:  
Exception: Error: [1000] Message: 	Font file could not be found

The above exception was the direct cause of the following exception:

Traceback (most recent call last):
  File "C:\Users\Giogina\SpectraMatcher\venv_win\lib\site-packages\dearpygui\dearpygui.py", line 2842, in window
    yield widget
  File "C:\Users\Giogina\SpectraMatcher\views\create_project.py", line 64, in __init__
    callback=self.on_close), Icons.x, 16)
  File "C:\Users\Giogina\SpectraMatcher\utility\icons.py", line 368, in insert
    label = self.get_icon(icon, size, solid)
  File "C:\Users\Giogina\SpectraMatcher\utility\icons.py", line 347, in get_icon
    with dpg.font(os.path.join(self._fonts_path, "Font Awesome 6 Free-Solid-900.otf"), size, parent=self._font_reg) as self._fs[size]:
  File "C:\Python37\lib\contextlib.py", line 112, in __enter__
    return next(self.gen)
  File "C:\Users\Giogina\SpectraMatcher\venv_win\lib\site-packages\dearpygui\dearpygui.py", line 1878, in font
    widget = internal_dpg.add_font(file, size, label=label, user_data=user_data, use_internal_label=use_internal_label, tag=tag, pixel_snapH=pixel_snapH, parent=parent, **kwargs)
SystemError: <built-in function add_font> returned a result with an error set

During handling of the above exception, another exception occurred:

Exception: Error: [1009] Message: 	No container to pop.

The above exception was the direct cause of the following exception:

Traceback (most recent call last):
  File "C:/Users/Giogina/SpectraMatcher/main.py", line 46, in <module>
    main()
  File "C:/Users/Giogina/SpectraMatcher/main.py", line 33, in main
    flags = CreateProjectWindow().show()
  File "C:\Users\Giogina\SpectraMatcher\views\create_project.py", line 118, in __init__
    dpg.add_button(label="Cancel", width=100, callback=lambda: dpg.configure_item("modal_id", show=False))
  File "C:\Python37\lib\contextlib.py", line 130, in __exit__
    self.gen.throw(type, value, traceback)
  File "C:\Users\Giogina\SpectraMatcher\venv_win\lib\site-packages\dearpygui\dearpygui.py", line 2844, in window
    internal_dpg.pop_container_stack()
SystemError: <built-in function pop_container_stack> returned a result with an error set
